
2021-05-07 02:17:14,027 INFO: errors [in c:\Users\User\FSND-master\projects\01_fyyur\starter_code\app.py:986]
2021-05-07 02:17:29,843 ERROR: Exception on /venues/create [GET] [in C:\Users\User\AppData\Local\Programs\Python\Python39\lib\site-packages\flask\app.py:1777]
Traceback (most recent call last):
  File "C:\Users\User\AppData\Local\Programs\Python\Python39\lib\site-packages\flask\app.py", line 2311, in wsgi_app
    response = self.full_dispatch_request()
  File "C:\Users\User\AppData\Local\Programs\Python\Python39\lib\site-packages\flask\app.py", line 1834, in full_dispatch_request
    rv = self.handle_user_exception(e)
  File "C:\Users\User\AppData\Local\Programs\Python\Python39\lib\site-packages\flask\app.py", line 1737, in handle_user_exception
    reraise(exc_type, exc_value, tb)
  File "C:\Users\User\AppData\Local\Programs\Python\Python39\lib\site-packages\flask\_compat.py", line 36, in reraise
    raise value
  File "C:\Users\User\AppData\Local\Programs\Python\Python39\lib\site-packages\flask\app.py", line 1832, in full_dispatch_request
    rv = self.dispatch_request()
  File "C:\Users\User\AppData\Local\Programs\Python\Python39\lib\site-packages\flask\app.py", line 1818, in dispatch_request
    return self.view_functions[rule.endpoint](**req.view_args)
  File "c:\Users\User\FSND-master\projects\01_fyyur\starter_code\app.py", line 300, in create_venue_form
    form = VenueForm()
  File "C:\Users\User\AppData\Local\Programs\Python\Python39\lib\site-packages\wtforms\form.py", line 208, in __call__
    return type.__call__(cls, *args, **kwargs)
  File "C:\Users\User\AppData\Local\Programs\Python\Python39\lib\site-packages\flask_wtf\form.py", line 157, in __init__
    super(Form, self).__init__(*args, **kwargs)
  File "C:\Users\User\AppData\Local\Programs\Python\Python39\lib\site-packages\flask_wtf\form.py", line 87, in __init__
    super(FlaskForm, self).__init__(formdata=formdata, **kwargs)
  File "C:\Users\User\AppData\Local\Programs\Python\Python39\lib\site-packages\wtforms\form.py", line 274, in __init__
    self.process(formdata, obj, data=data, **kwargs)
  File "C:\Users\User\AppData\Local\Programs\Python\Python39\lib\site-packages\wtforms\form.py", line 131, in process
    field.process(formdata)
  File "C:\Users\User\AppData\Local\Programs\Python\Python39\lib\site-packages\wtforms\csrf\core.py", line 43, in process
    self.current_token = self.csrf_impl.generate_csrf_token(self)
  File "C:\Users\User\AppData\Local\Programs\Python\Python39\lib\site-packages\flask_wtf\csrf.py", line 139, in generate_csrf_token
    return generate_csrf(
  File "C:\Users\User\AppData\Local\Programs\Python\Python39\lib\site-packages\flask_wtf\csrf.py", line 33, in generate_csrf
    secret_key = _get_config(
  File "C:\Users\User\AppData\Local\Programs\Python\Python39\lib\site-packages\flask_wtf\csrf.py", line 128, in _get_config
    raise RuntimeError(message)
RuntimeError: A secret key is required to use CSRF.
2021-05-07 02:17:35,839 ERROR: Exception on /artists/create [GET] [in C:\Users\User\AppData\Local\Programs\Python\Python39\lib\site-packages\flask\app.py:1777]
Traceback (most recent call last):
  File "C:\Users\User\AppData\Local\Programs\Python\Python39\lib\site-packages\flask\app.py", line 2311, in wsgi_app
    response = self.full_dispatch_request()
  File "C:\Users\User\AppData\Local\Programs\Python\Python39\lib\site-packages\flask\app.py", line 1834, in full_dispatch_request
    rv = self.handle_user_exception(e)
  File "C:\Users\User\AppData\Local\Programs\Python\Python39\lib\site-packages\flask\app.py", line 1737, in handle_user_exception
    reraise(exc_type, exc_value, tb)
  File "C:\Users\User\AppData\Local\Programs\Python\Python39\lib\site-packages\flask\_compat.py", line 36, in reraise
    raise value
  File "C:\Users\User\AppData\Local\Programs\Python\Python39\lib\site-packages\flask\app.py", line 1832, in full_dispatch_request
    rv = self.dispatch_request()
  File "C:\Users\User\AppData\Local\Programs\Python\Python39\lib\site-packages\flask\app.py", line 1818, in dispatch_request
    return self.view_functions[rule.endpoint](**req.view_args)
  File "c:\Users\User\FSND-master\projects\01_fyyur\starter_code\app.py", line 809, in create_artist_form
    form = ArtistForm()
  File "C:\Users\User\AppData\Local\Programs\Python\Python39\lib\site-packages\wtforms\form.py", line 208, in __call__
    return type.__call__(cls, *args, **kwargs)
  File "C:\Users\User\AppData\Local\Programs\Python\Python39\lib\site-packages\flask_wtf\form.py", line 157, in __init__
    super(Form, self).__init__(*args, **kwargs)
  File "C:\Users\User\AppData\Local\Programs\Python\Python39\lib\site-packages\flask_wtf\form.py", line 87, in __init__
    super(FlaskForm, self).__init__(formdata=formdata, **kwargs)
  File "C:\Users\User\AppData\Local\Programs\Python\Python39\lib\site-packages\wtforms\form.py", line 274, in __init__
    self.process(formdata, obj, data=data, **kwargs)
  File "C:\Users\User\AppData\Local\Programs\Python\Python39\lib\site-packages\wtforms\form.py", line 131, in process
    field.process(formdata)
  File "C:\Users\User\AppData\Local\Programs\Python\Python39\lib\site-packages\wtforms\csrf\core.py", line 43, in process
    self.current_token = self.csrf_impl.generate_csrf_token(self)
  File "C:\Users\User\AppData\Local\Programs\Python\Python39\lib\site-packages\flask_wtf\csrf.py", line 139, in generate_csrf_token
    return generate_csrf(
  File "C:\Users\User\AppData\Local\Programs\Python\Python39\lib\site-packages\flask_wtf\csrf.py", line 33, in generate_csrf
    secret_key = _get_config(
  File "C:\Users\User\AppData\Local\Programs\Python\Python39\lib\site-packages\flask_wtf\csrf.py", line 128, in _get_config
    raise RuntimeError(message)
RuntimeError: A secret key is required to use CSRF.
2021-05-07 02:17:40,075 ERROR: Exception on /artists [GET] [in C:\Users\User\AppData\Local\Programs\Python\Python39\lib\site-packages\flask\app.py:1777]
Traceback (most recent call last):
  File "C:\Users\User\AppData\Local\Programs\Python\Python39\lib\site-packages\sqlalchemy\util\_collections.py", line 1008, in __call__
    return self.registry[key]
KeyError: <greenlet.greenlet object at 0x00000185C8B9ECA0 (otid=0x00000185C8B9DAC0) current active started main>

During handling of the above exception, another exception occurred:

Traceback (most recent call last):
  File "C:\Users\User\AppData\Local\Programs\Python\Python39\lib\site-packages\flask\app.py", line 2311, in wsgi_app
    response = self.full_dispatch_request()
  File "C:\Users\User\AppData\Local\Programs\Python\Python39\lib\site-packages\flask\app.py", line 1834, in full_dispatch_request
    rv = self.handle_user_exception(e)
  File "C:\Users\User\AppData\Local\Programs\Python\Python39\lib\site-packages\flask\app.py", line 1737, in handle_user_exception
    reraise(exc_type, exc_value, tb)
  File "C:\Users\User\AppData\Local\Programs\Python\Python39\lib\site-packages\flask\_compat.py", line 36, in reraise
    raise value
  File "C:\Users\User\AppData\Local\Programs\Python\Python39\lib\site-packages\flask\app.py", line 1832, in full_dispatch_request
    rv = self.dispatch_request()
  File "C:\Users\User\AppData\Local\Programs\Python\Python39\lib\site-packages\flask\app.py", line 1818, in dispatch_request
    return self.view_functions[rule.endpoint](**req.view_args)
  File "c:\Users\User\FSND-master\projects\01_fyyur\starter_code\app.py", line 426, in artists
    artists = Artist.query.all()
  File "C:\Users\User\AppData\Local\Programs\Python\Python39\lib\site-packages\flask_sqlalchemy\__init__.py", line 519, in __get__
    return type.query_class(mapper, session=self.sa.session())
  File "C:\Users\User\AppData\Local\Programs\Python\Python39\lib\site-packages\sqlalchemy\orm\scoping.py", line 129, in __call__
    return self.registry()
  File "C:\Users\User\AppData\Local\Programs\Python\Python39\lib\site-packages\sqlalchemy\util\_collections.py", line 1010, in __call__
    return self.registry.setdefault(key, self.createfunc())
  File "C:\Users\User\AppData\Local\Programs\Python\Python39\lib\site-packages\sqlalchemy\orm\session.py", line 4058, in __call__
    return self.class_(**local_kw)
  File "C:\Users\User\AppData\Local\Programs\Python\Python39\lib\site-packages\flask_sqlalchemy\__init__.py", line 137, in __init__
    track_modifications = app.config['SQLALCHEMY_TRACK_MODIFICATIONS']
KeyError: 'SQLALCHEMY_TRACK_MODIFICATIONS'
2021-05-07 02:18:35,268 INFO: errors [in C:\Users\User\FSND-master\projects\01_fyyur\starter_code\app.py:986]
2021-05-07 02:19:06,045 INFO: errors [in C:\Users\User\FSND-master\projects\01_fyyur\starter_code\app.py:986]
2021-05-07 02:19:14,285 INFO: errors [in C:\Users\User\FSND-master\projects\01_fyyur\starter_code\app.py:986]
